# Bug Fix: "Hand Complete with 0 Tricks" Issue

## Problem Identified

The issue was in the `_resolve_trick()` method in `backend/game_board.py`. When this method was called with an empty `current_trick` list, it would:

1. Initialize `trick_winner = None`
2. Skip the for loop (since `current_trick` was empty)
3. Try to access `self.teams[trick_winner]` where `trick_winner` is `None`
4. Raise a `KeyError: None` exception

This could happen due to:
- Concurrency issues in the async server
- State corruption during Redis save/restore operations
- Multiple calls to `_resolve_trick()` on the same game instance

When the exception occurred, the game state could become corrupted, leading to incorrect hand completion messages showing "0 tricks for both teams".

## Solution Implemented

### 1. Added Safety Checks to `_resolve_trick()` Method

**File:** `backend/game_board.py`  
**Lines:** 288-320

Added two critical safety checks:

```python
def _resolve_trick(self) -> Dict[str, Any]:
    """Determine trick winner and update game state"""
    # Safety check: ensure current_trick has exactly 4 cards
    if len(self.current_trick) != 4:
        raise ValueError(f"Cannot resolve trick: expected 4 cards, got {len(self.current_trick)}")
    
    # ... existing logic ...
    
    # Safety check: ensure we found a winner
    if trick_winner is None:
        raise ValueError(f"No trick winner found for trick: {self.current_trick}")
```

**Benefits:**
- Prevents the method from running with invalid input
- Provides clear error messages for debugging
- Ensures the method fails fast instead of corrupting game state

### 2. Enhanced Error Handling in Server

**File:** `backend/server.py`  
**Lines:** 483-498

Added specific error handling around `game.play_card()`:

```python
try:
    result = game.play_card(player, card, self.redis_manager)
except ValueError as ve:
    # This catches invalid game state errors (e.g., invalid trick resolution)
    error_msg = f"Invalid game state during card play: {str(ve)}"
    print(f"[ERROR] {error_msg}")
    await self.network_manager.notify_error(websocket, "Game state error. Please restart the game.")
    return
except Exception as e:
    # Catch any other unexpected errors during card play
    error_msg = f"Unexpected error during card play: {str(e)}"
    print(f"[ERROR] {error_msg}")
    await self.network_manager.notify_error(websocket, "Unexpected error. Please try again.")
    return
```

**Benefits:**
- Gracefully handles game state errors
- Provides meaningful error messages to players
- Prevents the server from crashing or sending invalid data

## Root Cause Analysis

The original server-side logic in `handle_play_card()` had this line:

```python
team_tricks = result.get('team_tricks') or {0: 0, 1: 0}
```

This was meant as a fallback for missing data, but the real issue was that `result.get('team_tricks')` was returning `{0: 0, 1: 0}` legitimately because:

1. `_resolve_trick()` was called with invalid state (empty `current_trick`)
2. The method crashed with `KeyError: None` 
3. Exception handling somewhere allowed the game to continue in a corrupted state
4. The hand completion logic was triggered with both teams having 0 tricks

## Testing

Created comprehensive tests to verify the fix:

**File:** `test_bug_fix.py`

Tests include:
- Empty `current_trick` handling
- Incomplete trick (< 4 cards) handling  
- Valid trick processing
- Server-side protection verification

**Results:**
- ✅ `_resolve_trick()` now correctly rejects invalid input with clear error messages
- ✅ Server gracefully handles game state errors
- ✅ Existing 7-trick rule functionality remains intact
- ✅ Bug reproduction scenario is now prevented

## Impact

**Before Fix:**
- Players could see "Hand Complete" with "Team 1: 0 tricks, Team 2: 0 tricks"
- Game state could become corrupted
- Confusing user experience

**After Fix:**
- Invalid game states are caught early and clearly reported
- Players receive meaningful error messages
- Game integrity is maintained
- Server logs provide debugging information

## Files Modified

1. `backend/game_board.py` - Added safety checks to `_resolve_trick()`
2. `backend/server.py` - Enhanced error handling in `handle_play_card()`
3. `test_bug_fix.py` - Created comprehensive tests for the fix

## Verification

The fix has been tested and verified to:
- ✅ Prevent the "Hand Complete with 0 tricks" bug
- ✅ Maintain all existing game functionality
- ✅ Provide better error handling and debugging
- ✅ Pass all existing tests including the 7-trick rule tests

The bug is now resolved and the game should provide a much more stable and reliable experience.
